2025-05-03 16:45:20,724 - MLServer - INFO - Server started on port 50051
2025-05-03 16:45:20,724 - MLServer - INFO - Waiting for requests...
2025-05-03 16:45:27,142 - grpc._server - ERROR - Exception iterating responses: module 'ml.v1.service_pb2' has no attribute 'ScenarioType'
Traceback (most recent call last):
  File "/home/artem216/diploma/ml/.venv/lib/python3.11/site-packages/grpc/_server.py", line 654, in _take_response_from_response_iterator
    return next(response_iterator), True
           ^^^^^^^^^^^^^^^^^^^^^^^
  File "/home/artem216/diploma/ml/src/server.py", line 22, in ProcessQuery
    f"Scenario: {ml_pb2.ScenarioType.Name(request.scenario.customType)}\n"
                 ^^^^^^^^^^^^^^^^^^^
AttributeError: module 'ml.v1.service_pb2' has no attribute 'ScenarioType'
2025-05-03 16:47:54,057 - MLServer - INFO - Shutting down server...
2025-05-03 16:47:54,057 - MLServer - INFO - Server stopped gracefully
2025-05-03 17:10:12,981 - MLServer - INFO - Server started on port 50051
2025-05-03 17:10:12,981 - MLServer - INFO - Waiting for requests...
2025-05-03 17:10:26,440 - MLServer - INFO - Shutting down server...
2025-05-03 17:10:26,441 - MLServer - INFO - Server stopped gracefully
2025-05-03 17:14:01,175 - MLServer - INFO - Server started on port 50051
2025-05-03 17:14:01,175 - MLServer - INFO - Waiting for requests...
2025-05-03 17:14:43,388 - MLServer - INFO - Shutting down server...
2025-05-03 17:14:43,388 - MLServer - INFO - Server stopped gracefully
2025-05-03 17:27:52,284 - MLServer - INFO - Server started on port 50051
2025-05-03 17:27:52,284 - MLServer - INFO - Waiting for requests...
2025-05-03 17:28:08,437 - MLServer - INFO - New request [ID:1-3076207046145985200] from 33878
User: 1
Content length: 18
Scenario: UNDEFINED_SCENARIO
Documents: 2
2025-05-03 17:28:26,865 - MLServer - INFO - Shutting down server...
2025-05-03 17:28:26,865 - MLServer - INFO - Server stopped gracefully
2025-05-04 21:44:27,076 - MLServer - INFO - Server started on port 50051
2025-05-04 21:44:27,076 - MLServer - INFO - Waiting for requests...
2025-05-04 21:44:30,160 - MLServer - INFO - New request [ID:1-5124726172396843842] from 47318
User: 1
Content length: 16
Scenario: UNDEFINED_SCENARIO
Documents: 1
2025-05-04 21:44:30,166 - MLServer - ERROR - Error processing request 1-5124726172396843842: API request failed: HTTPConnectionPool(host='localhost', port=11434): Max retries exceeded with url: /api/generate (Caused by NewConnectionError('<urllib3.connection.HTTPConnection object at 0x7f219cabc150>: Failed to establish a new connection: [Errno 111] Connection refused'))
Traceback: Traceback (most recent call last):
  File "/home/artem216/diploma/ml/.venv/lib/python3.11/site-packages/urllib3/connection.py", line 198, in _new_conn
    sock = connection.create_connection(
           ^^^^^^^^^^^^^^^^^^^^^^^^^^^^^
  File "/home/artem216/diploma/ml/.venv/lib/python3.11/site-packages/urllib3/util/connection.py", line 85, in create_connection
    raise err
  File "/home/artem216/diploma/ml/.venv/lib/python3.11/site-packages/urllib3/util/connection.py", line 73, in create_connection
    sock.connect(sa)
ConnectionRefusedError: [Errno 111] Connection refused

The above exception was the direct cause of the following exception:

Traceback (most recent call last):
  File "/home/artem216/diploma/ml/.venv/lib/python3.11/site-packages/urllib3/connectionpool.py", line 787, in urlopen
    response = self._make_request(
               ^^^^^^^^^^^^^^^^^^^
  File "/home/artem216/diploma/ml/.venv/lib/python3.11/site-packages/urllib3/connectionpool.py", line 493, in _make_request
    conn.request(
  File "/home/artem216/diploma/ml/.venv/lib/python3.11/site-packages/urllib3/connection.py", line 445, in request
    self.endheaders()
  File "/usr/lib/python3.11/http/client.py", line 1298, in endheaders
    self._send_output(message_body, encode_chunked=encode_chunked)
  File "/usr/lib/python3.11/http/client.py", line 1058, in _send_output
    self.send(msg)
  File "/usr/lib/python3.11/http/client.py", line 996, in send
    self.connect()
  File "/home/artem216/diploma/ml/.venv/lib/python3.11/site-packages/urllib3/connection.py", line 276, in connect
    self.sock = self._new_conn()
                ^^^^^^^^^^^^^^^^
  File "/home/artem216/diploma/ml/.venv/lib/python3.11/site-packages/urllib3/connection.py", line 213, in _new_conn
    raise NewConnectionError(
urllib3.exceptions.NewConnectionError: <urllib3.connection.HTTPConnection object at 0x7f219cabc150>: Failed to establish a new connection: [Errno 111] Connection refused

The above exception was the direct cause of the following exception:

Traceback (most recent call last):
  File "/home/artem216/diploma/ml/.venv/lib/python3.11/site-packages/requests/adapters.py", line 667, in send
    resp = conn.urlopen(
           ^^^^^^^^^^^^^
  File "/home/artem216/diploma/ml/.venv/lib/python3.11/site-packages/urllib3/connectionpool.py", line 841, in urlopen
    retries = retries.increment(
              ^^^^^^^^^^^^^^^^^^
  File "/home/artem216/diploma/ml/.venv/lib/python3.11/site-packages/urllib3/util/retry.py", line 519, in increment
    raise MaxRetryError(_pool, url, reason) from reason  # type: ignore[arg-type]
    ^^^^^^^^^^^^^^^^^^^^^^^^^^^^^^^^^^^^^^^^^^^^^^^^^^^
urllib3.exceptions.MaxRetryError: HTTPConnectionPool(host='localhost', port=11434): Max retries exceeded with url: /api/generate (Caused by NewConnectionError('<urllib3.connection.HTTPConnection object at 0x7f219cabc150>: Failed to establish a new connection: [Errno 111] Connection refused'))

During handling of the above exception, another exception occurred:

Traceback (most recent call last):
  File "/home/artem216/diploma/ml/src/ollama_client.py", line 63, in generate
    response = requests.post(
               ^^^^^^^^^^^^^^
  File "/home/artem216/diploma/ml/.venv/lib/python3.11/site-packages/requests/api.py", line 115, in post
    return request("post", url, data=data, json=json, **kwargs)
           ^^^^^^^^^^^^^^^^^^^^^^^^^^^^^^^^^^^^^^^^^^^^^^^^^^^^
  File "/home/artem216/diploma/ml/.venv/lib/python3.11/site-packages/requests/api.py", line 59, in request
    return session.request(method=method, url=url, **kwargs)
           ^^^^^^^^^^^^^^^^^^^^^^^^^^^^^^^^^^^^^^^^^^^^^^^^^
  File "/home/artem216/diploma/ml/.venv/lib/python3.11/site-packages/requests/sessions.py", line 589, in request
    resp = self.send(prep, **send_kwargs)
           ^^^^^^^^^^^^^^^^^^^^^^^^^^^^^^
  File "/home/artem216/diploma/ml/.venv/lib/python3.11/site-packages/requests/sessions.py", line 703, in send
    r = adapter.send(request, **kwargs)
        ^^^^^^^^^^^^^^^^^^^^^^^^^^^^^^^
  File "/home/artem216/diploma/ml/.venv/lib/python3.11/site-packages/requests/adapters.py", line 700, in send
    raise ConnectionError(e, request=request)
requests.exceptions.ConnectionError: HTTPConnectionPool(host='localhost', port=11434): Max retries exceeded with url: /api/generate (Caused by NewConnectionError('<urllib3.connection.HTTPConnection object at 0x7f219cabc150>: Failed to establish a new connection: [Errno 111] Connection refused'))

The above exception was the direct cause of the following exception:

Traceback (most recent call last):
  File "/home/artem216/diploma/ml/src/server.py", line 54, in ProcessQuery
    perefrazing_questions = get_multi_questions(
                            ^^^^^^^^^^^^^^^^^^^^
  File "/home/artem216/diploma/ml/src/multi_query.py", line 45, in get_multi_questions
    client.generate(
  File "/home/artem216/diploma/ml/src/ollama_client.py", line 73, in generate
    raise RuntimeError(f"API request failed: {e}") from e
RuntimeError: API request failed: HTTPConnectionPool(host='localhost', port=11434): Max retries exceeded with url: /api/generate (Caused by NewConnectionError('<urllib3.connection.HTTPConnection object at 0x7f219cabc150>: Failed to establish a new connection: [Errno 111] Connection refused'))

2025-05-04 21:45:48,655 - MLServer - INFO - Shutting down server...
2025-05-04 21:45:48,656 - MLServer - INFO - Server stopped gracefully
2025-05-04 22:02:59,758 - MLServer - INFO - Server started on port 50051
2025-05-04 22:02:59,758 - MLServer - INFO - Waiting for requests...
2025-05-04 22:03:09,304 - MLServer - INFO - New request [ID:1--8840242509482018521] from 48658
User: 1
Content length: 16
Scenario: UNDEFINED_SCENARIO
Documents: 1
2025-05-04 22:03:55,041 - MLServer - INFO - Shutting down server...
2025-05-04 22:03:55,043 - MLServer - INFO - Server stopped gracefully
2025-05-04 22:05:56,961 - MLServer - INFO - Server started on port 50051
2025-05-04 22:05:56,962 - MLServer - INFO - Waiting for requests...
2025-05-04 22:05:58,678 - MLServer - INFO - New request [ID:1--7139683273006806439] from 46062
User: 1
Content length: 16
Scenario: UNDEFINED_SCENARIO
Documents: 1
2025-05-04 22:06:37,684 - MLServer - INFO - Shutting down server...
2025-05-04 22:06:37,685 - MLServer - INFO - Server stopped gracefully
2025-05-04 22:30:32,503 - MLServer - INFO - Server started on port 50051
2025-05-04 22:30:32,504 - MLServer - INFO - Waiting for requests...
2025-05-04 22:30:52,600 - MLServer - INFO - New request [ID:1--8838157336728322260] from 36302
User: 1
Content length: 16
Scenario: UNDEFINED_SCENARIO
Documents: 1
2025-05-04 22:32:41,908 - MLServer - INFO - Shutting down server...
2025-05-04 22:32:41,909 - MLServer - INFO - Server stopped gracefully
